package sample.coroutines.exception

import kotlinx.coroutines.CoroutineExceptionHandler
import kotlinx.coroutines.GlobalScope
import kotlinx.coroutines.async
import kotlinx.coroutines.joinAll
import kotlinx.coroutines.launch
import kotlinx.coroutines.runBlocking

fun main() = runBlocking {
    val handler = CoroutineExceptionHandler { _, exception ->
        println("Caught $exception")
    }
    val job = GlobalScope.launch(handler) {
        throw AssertionError()
    }
    val deferred = GlobalScope.async(handler) {
        throw ArithmeticException() // Nothing will be printed, relying on user to call deferred.await()
    }
    joinAll(job, deferred)
}